{
  "cells": [
    {
      "cell_type": "markdown",
      "metadata": {
        "id": "Dt5-VycYSpHu"
      },
      "source": [
        "# Detecting Faces with and without masks\n",
        "\n",
        "![detecting.png](attachment:detecting.png)"
      ]
    },
    {
      "cell_type": "code",
      "execution_count": 8,
      "metadata": {
        "id": "srGGbyqqSpH1",
        "outputId": "4cff49d6-7ccd-47a9-bd77-3b0830f23d3c"
      },
      "outputs": [],
      "source": [
        "from keras.models import load_model\n",
        "import cv2\n",
        "import numpy as np\n",
        "from tensorflow import expand_dims\n",
        "from tensorflow.image import decode_image, resize"
      ]
    },
    {
      "cell_type": "code",
      "execution_count": 9,
      "metadata": {
        "id": "lfiHVrnXSpH3"
      },
      "outputs": [],
      "source": [
        "model = load_model('model_tl.h5')\n",
        "\n",
        "face_clsfr=cv2.CascadeClassifier(cv2.data.haarcascades + 'haarcascade_frontalface_default.xml')\n",
        "\n",
        "source=cv2.VideoCapture(0)\n",
        "\n",
        "labels_dict={0:'INCORRECT MASK',1:'WITH MASK',2:'WITHOUT MASK'}\n",
        "color_dict={0:(0,0,255),1:(0,255,0),2:(0,0,255)}"
      ]
    },
    {
      "cell_type": "code",
      "execution_count": 19,
      "metadata": {
        "id": "AIpTqIxESpH5"
      },
      "outputs": [
        {
          "name": "stdout",
          "output_type": "stream",
          "text": [
            "WARNING:tensorflow:Model was constructed with shape (None, 300, 300, 3) for input KerasTensor(type_spec=TensorSpec(shape=(None, 300, 300, 3), dtype=tf.float32, name='input_2'), name='input_2', description=\"created by layer 'input_2'\"), but it was called on an input with incompatible shape (None, 300, 1).\n",
            "WARNING:tensorflow:Model was constructed with shape (None, 300, 300, 3) for input KerasTensor(type_spec=TensorSpec(shape=(None, 300, 300, 3), dtype=tf.float32, name='input_1'), name='input_1', description=\"created by layer 'input_1'\"), but it was called on an input with incompatible shape (None, 300, 1).\n"
          ]
        },
        {
          "ename": "ValueError",
          "evalue": "in user code:\n\n    File \"C:\\Users\\user\\AppData\\Local\\Programs\\Python\\Python310\\lib\\site-packages\\keras\\engine\\training.py\", line 1801, in predict_function  *\n        return step_function(self, iterator)\n    File \"C:\\Users\\user\\AppData\\Local\\Programs\\Python\\Python310\\lib\\site-packages\\keras\\engine\\training.py\", line 1790, in step_function  **\n        outputs = model.distribute_strategy.run(run_step, args=(data,))\n    File \"C:\\Users\\user\\AppData\\Local\\Programs\\Python\\Python310\\lib\\site-packages\\keras\\engine\\training.py\", line 1783, in run_step  **\n        outputs = model.predict_step(data)\n    File \"C:\\Users\\user\\AppData\\Local\\Programs\\Python\\Python310\\lib\\site-packages\\keras\\engine\\training.py\", line 1751, in predict_step\n        return self(x, training=False)\n    File \"C:\\Users\\user\\AppData\\Local\\Programs\\Python\\Python310\\lib\\site-packages\\keras\\utils\\traceback_utils.py\", line 67, in error_handler\n        raise e.with_traceback(filtered_tb) from None\n    File \"C:\\Users\\user\\AppData\\Local\\Programs\\Python\\Python310\\lib\\site-packages\\keras\\engine\\input_spec.py\", line 214, in assert_input_compatibility\n        raise ValueError(f'Input {input_index} of layer \"{layer_name}\" '\n\n    ValueError: Exception encountered when calling layer \"resnet50v2\" (type Functional).\n    \n    Input 0 of layer \"conv1_pad\" is incompatible with the layer: expected ndim=4, found ndim=3. Full shape received: (None, 300, 1)\n    \n    Call arguments received:\n      • inputs=tf.Tensor(shape=(None, 300, 1), dtype=float32)\n      • training=False\n      • mask=None\n",
          "output_type": "error",
          "traceback": [
            "\u001b[1;31m---------------------------------------------------------------------------\u001b[0m",
            "\u001b[1;31mValueError\u001b[0m                                Traceback (most recent call last)",
            "\u001b[1;32m~\\AppData\\Local\\Temp/ipykernel_14412/1999219429.py\u001b[0m in \u001b[0;36m<module>\u001b[1;34m\u001b[0m\n\u001b[0;32m     14\u001b[0m         \u001b[1;31m# reshaped = expand_dims(normalized, axis=0)\u001b[0m\u001b[1;33m\u001b[0m\u001b[1;33m\u001b[0m\u001b[0m\n\u001b[0;32m     15\u001b[0m         \u001b[0mreshaped\u001b[0m\u001b[1;33m=\u001b[0m\u001b[0mnp\u001b[0m\u001b[1;33m.\u001b[0m\u001b[0mreshape\u001b[0m\u001b[1;33m(\u001b[0m\u001b[0mnormalized\u001b[0m\u001b[1;33m,\u001b[0m\u001b[1;33m(\u001b[0m\u001b[1;36m300\u001b[0m\u001b[1;33m,\u001b[0m\u001b[1;36m300\u001b[0m\u001b[1;33m,\u001b[0m\u001b[1;36m1\u001b[0m\u001b[1;33m)\u001b[0m\u001b[1;33m)\u001b[0m\u001b[1;33m\u001b[0m\u001b[1;33m\u001b[0m\u001b[0m\n\u001b[1;32m---> 16\u001b[1;33m         \u001b[0mresult\u001b[0m\u001b[1;33m=\u001b[0m\u001b[0mmodel\u001b[0m\u001b[1;33m.\u001b[0m\u001b[0mpredict\u001b[0m\u001b[1;33m(\u001b[0m\u001b[0mreshaped\u001b[0m\u001b[1;33m)\u001b[0m\u001b[1;33m\u001b[0m\u001b[1;33m\u001b[0m\u001b[0m\n\u001b[0m\u001b[0;32m     17\u001b[0m \u001b[1;33m\u001b[0m\u001b[0m\n\u001b[0;32m     18\u001b[0m         \u001b[1;31m# face_img=gray[y:y+w,x:x+w]\u001b[0m\u001b[1;33m\u001b[0m\u001b[1;33m\u001b[0m\u001b[0m\n",
            "\u001b[1;32m~\\AppData\\Local\\Programs\\Python\\Python310\\lib\\site-packages\\keras\\utils\\traceback_utils.py\u001b[0m in \u001b[0;36merror_handler\u001b[1;34m(*args, **kwargs)\u001b[0m\n\u001b[0;32m     65\u001b[0m     \u001b[1;32mexcept\u001b[0m \u001b[0mException\u001b[0m \u001b[1;32mas\u001b[0m \u001b[0me\u001b[0m\u001b[1;33m:\u001b[0m  \u001b[1;31m# pylint: disable=broad-except\u001b[0m\u001b[1;33m\u001b[0m\u001b[1;33m\u001b[0m\u001b[0m\n\u001b[0;32m     66\u001b[0m       \u001b[0mfiltered_tb\u001b[0m \u001b[1;33m=\u001b[0m \u001b[0m_process_traceback_frames\u001b[0m\u001b[1;33m(\u001b[0m\u001b[0me\u001b[0m\u001b[1;33m.\u001b[0m\u001b[0m__traceback__\u001b[0m\u001b[1;33m)\u001b[0m\u001b[1;33m\u001b[0m\u001b[1;33m\u001b[0m\u001b[0m\n\u001b[1;32m---> 67\u001b[1;33m       \u001b[1;32mraise\u001b[0m \u001b[0me\u001b[0m\u001b[1;33m.\u001b[0m\u001b[0mwith_traceback\u001b[0m\u001b[1;33m(\u001b[0m\u001b[0mfiltered_tb\u001b[0m\u001b[1;33m)\u001b[0m \u001b[1;32mfrom\u001b[0m \u001b[1;32mNone\u001b[0m\u001b[1;33m\u001b[0m\u001b[1;33m\u001b[0m\u001b[0m\n\u001b[0m\u001b[0;32m     68\u001b[0m     \u001b[1;32mfinally\u001b[0m\u001b[1;33m:\u001b[0m\u001b[1;33m\u001b[0m\u001b[1;33m\u001b[0m\u001b[0m\n\u001b[0;32m     69\u001b[0m       \u001b[1;32mdel\u001b[0m \u001b[0mfiltered_tb\u001b[0m\u001b[1;33m\u001b[0m\u001b[1;33m\u001b[0m\u001b[0m\n",
            "\u001b[1;32m~\\AppData\\Local\\Programs\\Python\\Python310\\lib\\site-packages\\tensorflow\\python\\framework\\func_graph.py\u001b[0m in \u001b[0;36mautograph_handler\u001b[1;34m(*args, **kwargs)\u001b[0m\n\u001b[0;32m   1145\u001b[0m           \u001b[1;32mexcept\u001b[0m \u001b[0mException\u001b[0m \u001b[1;32mas\u001b[0m \u001b[0me\u001b[0m\u001b[1;33m:\u001b[0m  \u001b[1;31m# pylint:disable=broad-except\u001b[0m\u001b[1;33m\u001b[0m\u001b[1;33m\u001b[0m\u001b[0m\n\u001b[0;32m   1146\u001b[0m             \u001b[1;32mif\u001b[0m \u001b[0mhasattr\u001b[0m\u001b[1;33m(\u001b[0m\u001b[0me\u001b[0m\u001b[1;33m,\u001b[0m \u001b[1;34m\"ag_error_metadata\"\u001b[0m\u001b[1;33m)\u001b[0m\u001b[1;33m:\u001b[0m\u001b[1;33m\u001b[0m\u001b[1;33m\u001b[0m\u001b[0m\n\u001b[1;32m-> 1147\u001b[1;33m               \u001b[1;32mraise\u001b[0m \u001b[0me\u001b[0m\u001b[1;33m.\u001b[0m\u001b[0mag_error_metadata\u001b[0m\u001b[1;33m.\u001b[0m\u001b[0mto_exception\u001b[0m\u001b[1;33m(\u001b[0m\u001b[0me\u001b[0m\u001b[1;33m)\u001b[0m\u001b[1;33m\u001b[0m\u001b[1;33m\u001b[0m\u001b[0m\n\u001b[0m\u001b[0;32m   1148\u001b[0m             \u001b[1;32melse\u001b[0m\u001b[1;33m:\u001b[0m\u001b[1;33m\u001b[0m\u001b[1;33m\u001b[0m\u001b[0m\n\u001b[0;32m   1149\u001b[0m               \u001b[1;32mraise\u001b[0m\u001b[1;33m\u001b[0m\u001b[1;33m\u001b[0m\u001b[0m\n",
            "\u001b[1;31mValueError\u001b[0m: in user code:\n\n    File \"C:\\Users\\user\\AppData\\Local\\Programs\\Python\\Python310\\lib\\site-packages\\keras\\engine\\training.py\", line 1801, in predict_function  *\n        return step_function(self, iterator)\n    File \"C:\\Users\\user\\AppData\\Local\\Programs\\Python\\Python310\\lib\\site-packages\\keras\\engine\\training.py\", line 1790, in step_function  **\n        outputs = model.distribute_strategy.run(run_step, args=(data,))\n    File \"C:\\Users\\user\\AppData\\Local\\Programs\\Python\\Python310\\lib\\site-packages\\keras\\engine\\training.py\", line 1783, in run_step  **\n        outputs = model.predict_step(data)\n    File \"C:\\Users\\user\\AppData\\Local\\Programs\\Python\\Python310\\lib\\site-packages\\keras\\engine\\training.py\", line 1751, in predict_step\n        return self(x, training=False)\n    File \"C:\\Users\\user\\AppData\\Local\\Programs\\Python\\Python310\\lib\\site-packages\\keras\\utils\\traceback_utils.py\", line 67, in error_handler\n        raise e.with_traceback(filtered_tb) from None\n    File \"C:\\Users\\user\\AppData\\Local\\Programs\\Python\\Python310\\lib\\site-packages\\keras\\engine\\input_spec.py\", line 214, in assert_input_compatibility\n        raise ValueError(f'Input {input_index} of layer \"{layer_name}\" '\n\n    ValueError: Exception encountered when calling layer \"resnet50v2\" (type Functional).\n    \n    Input 0 of layer \"conv1_pad\" is incompatible with the layer: expected ndim=4, found ndim=3. Full shape received: (None, 300, 1)\n    \n    Call arguments received:\n      • inputs=tf.Tensor(shape=(None, 300, 1), dtype=float32)\n      • training=False\n      • mask=None\n"
          ]
        }
      ],
      "source": [
        "while(True):\n",
        "\n",
        "    ret,img=source.read()\n",
        "    gray=cv2.cvtColor(img,cv2.COLOR_BGR2GRAY)\n",
        "    faces=face_clsfr.detectMultiScale(gray,1.3,5)  \n",
        "\n",
        "    for x,y,w,h in faces:\n",
        "    \n",
        "        face_img=gray[y:y+w,x:x+w]\n",
        "        # face_img = decode_image(face_img, channels=3)\n",
        "        resized=cv2.resize(face_img,(300,300))\n",
        "        # resized=cv2.resize(img,(int(img.shape[1]/3)),(int(img.shape[0]/3)))\n",
        "        normalized=resized/255.0\n",
        "        # reshaped = expand_dims(normalized, axis=0)\n",
        "        reshaped=np.reshape(normalized,(300,300,1))\n",
        "        result=model.predict(reshaped)\n",
        "\n",
        "        # face_img=gray[y:y+w,x:x+w]\n",
        "        # shape = ((300, 300, 3))\n",
        "        # test_image = face_img.resize((300, 300)) #resize\n",
        "        # test_image = preprocessing.image.img_to_array(test_image) #img to array\n",
        "        # test_image = test_image/255.0 #rescale\n",
        "\n",
        "        label=np.argmax(result,axis=1)[0]\n",
        "      \n",
        "        cv2.rectangle(img,(x,y),(x+w,y+h),color_dict[label],2)\n",
        "        cv2.rectangle(img,(x,y-40),(x+w,y),color_dict[label],-1)\n",
        "        cv2.putText(img, labels_dict[label], (x, y-10),cv2.FONT_HERSHEY_SIMPLEX,0.8,(255,255,255),2)\n",
        "        \n",
        "        \n",
        "    cv2.imshow('LIVE',img)\n",
        "    key=cv2.waitKey(1)\n",
        "    \n",
        "    if(key==27):\n",
        "        break\n",
        "        \n",
        "cv2.destroyAllWindows()\n",
        "source.release()"
      ]
    },
    {
      "cell_type": "markdown",
      "metadata": {
        "id": "5TBeCoQvSpH6"
      },
      "source": [
        "![argmax.png](attachment:argmax.png)"
      ]
    },
    {
      "cell_type": "markdown",
      "metadata": {
        "id": "bJ7u3s7ZSpH7"
      },
      "source": [
        "## Motivated by the works of,\n",
        "\n",
        "1. [Adrian Rosebrock](https://www.pyimagesearch.com/2020/05/04/covid-19-face-mask-detector-with-opencv-keras-tensorflow-and-deep-learning/)\n",
        "2. [sentdex](https://pythonprogramming.net/convolutional-neural-network-deep-learning-python-tensorflow-keras/)\n",
        "3. [Prajna Bhandary](https://github.com/prajnasb/observations/tree/master/experiements/data)"
      ]
    }
  ],
  "metadata": {
    "colab": {
      "name": "3.0 detecting Masks.ipynb",
      "provenance": []
    },
    "kernelspec": {
      "display_name": "Python 3",
      "language": "python",
      "name": "python3"
    },
    "language_info": {
      "codemirror_mode": {
        "name": "ipython",
        "version": 3
      },
      "file_extension": ".py",
      "mimetype": "text/x-python",
      "name": "python",
      "nbconvert_exporter": "python",
      "pygments_lexer": "ipython3",
      "version": "3.10.0"
    }
  },
  "nbformat": 4,
  "nbformat_minor": 0
}
